<?xml version="1.0"?>
<!-- KUKA KR6 R700 sixx URDF with proper 3D meshes from ROS-Industrial -->
<!-- Source: ros-industrial/kuka_experimental/kuka_kr6_support -->
<!-- Inertial values computed from KUKA datasheet: 52kg total, 6kg payload -->
<robot xmlns:xacro="http://www.ros.org/wiki/xacro" name="kr6_r700">

  <!-- World link: anchors the robot to the ground -->
  <link name="world"/>
  <joint name="world_to_base" type="fixed">
    <parent link="world"/>
    <child link="base_link"/>
    <origin xyz="0 0 0" rpy="0 0 0"/>
  </joint>

  <link name="base_link">
    <visual>
      <origin xyz="0 0 0" rpy="0 0 0"/>
      <geometry>
        <mesh filename="package://kuka_kr6_gazebo/meshes/visual/base_link.dae"/>
      </geometry>
    </visual>
    <collision>
      <origin xyz="0 0 0" rpy="0 0 0"/>
      <geometry>
        <mesh filename="package://kuka_kr6_gazebo/meshes/collision/base_link.stl"/>
      </geometry>
    </collision>
    <inertial>
      <mass value="15.0"/>
      <origin xyz="0 0 0.15" rpy="0 0 0"/>
      <inertia ixx="0.15" ixy="0" ixz="0" iyy="0.15" iyz="0" izz="0.10"/>
    </inertial>
  </link>

  <link name="link_1">
    <visual>
      <origin xyz="0 0 0" rpy="0 0 0"/>
      <geometry>
        <mesh filename="package://kuka_kr6_gazebo/meshes/visual/link_1.dae"/>
      </geometry>
    </visual>
    <collision>
      <origin xyz="0 0 0" rpy="0 0 0"/>
      <geometry>
        <mesh filename="package://kuka_kr6_gazebo/meshes/collision/link_1.stl"/>
      </geometry>
    </collision>
    <inertial>
      <mass value="12.0"/>
      <origin xyz="0 0 0.0" rpy="0 0 0"/>
      <inertia ixx="0.08" ixy="0" ixz="0" iyy="0.08" iyz="0" izz="0.06"/>
    </inertial>
  </link>

  <link name="link_2">
    <visual>
      <origin xyz="0 0 0" rpy="0 0 0"/>
      <geometry>
        <mesh filename="package://kuka_kr6_gazebo/meshes/visual/link_2.dae"/>
      </geometry>
    </visual>
    <collision>
      <origin xyz="0 0 0" rpy="0 0 0"/>
      <geometry>
        <mesh filename="package://kuka_kr6_gazebo/meshes/collision/link_2.stl"/>
      </geometry>
    </collision>
    <inertial>
      <mass value="10.0"/>
      <origin xyz="0.15 0 0" rpy="0 0 0"/>
      <inertia ixx="0.03" ixy="0" ixz="0" iyy="0.20" iyz="0" izz="0.20"/>
    </inertial>
  </link>

  <link name="link_3">
    <visual>
      <origin xyz="0 0 0" rpy="0 0 0"/>
      <geometry>
        <mesh filename="package://kuka_kr6_gazebo/meshes/visual/link_3.dae"/>
      </geometry>
    </visual>
    <collision>
      <origin xyz="0 0 0" rpy="0 0 0"/>
      <geometry>
        <mesh filename="package://kuka_kr6_gazebo/meshes/collision/link_3.stl"/>
      </geometry>
    </collision>
    <inertial>
      <mass value="5.0"/>
      <origin xyz="0 0 0.02" rpy="0 0 0"/>
      <inertia ixx="0.02" ixy="0" ixz="0" iyy="0.02" iyz="0" izz="0.01"/>
    </inertial>
  </link>

  <link name="link_4">
    <visual>
      <origin xyz="0 0 0" rpy="0 0 0"/>
      <geometry>
        <mesh filename="package://kuka_kr6_gazebo/meshes/visual/link_4.dae"/>
      </geometry>
    </visual>
    <collision>
      <origin xyz="0 0 0" rpy="0 0 0"/>
      <geometry>
        <mesh filename="package://kuka_kr6_gazebo/meshes/collision/link_4.stl"/>
      </geometry>
    </collision>
    <inertial>
      <mass value="4.0"/>
      <origin xyz="0.18 0 0" rpy="0 0 0"/>
      <inertia ixx="0.005" ixy="0" ixz="0" iyy="0.05" iyz="0" izz="0.05"/>
    </inertial>
  </link>

  <link name="link_5">
    <visual>
      <origin xyz="0 0 0" rpy="0 0 0"/>
      <geometry>
        <mesh filename="package://kuka_kr6_gazebo/meshes/visual/link_5.dae"/>
      </geometry>
    </visual>
    <collision>
      <origin xyz="0 0 0" rpy="0 0 0"/>
      <geometry>
        <mesh filename="package://kuka_kr6_gazebo/meshes/collision/link_5.stl"/>
      </geometry>
    </collision>
    <inertial>
      <mass value="2.0"/>
      <origin xyz="0 0 0" rpy="0 0 0"/>
      <inertia ixx="0.003" ixy="0" ixz="0" iyy="0.003" iyz="0" izz="0.002"/>
    </inertial>
  </link>

  <link name="link_6">
    <visual>
      <origin xyz="0 0 0" rpy="0 0 0"/>
      <geometry>
        <mesh filename="package://kuka_kr6_gazebo/meshes/visual/link_6.dae"/>
      </geometry>
    </visual>
    <collision>
      <origin xyz="0 0 0" rpy="0 0 0"/>
      <geometry>
        <mesh filename="package://kuka_kr6_gazebo/meshes/collision/link_6.stl"/>
      </geometry>
    </collision>
    <inertial>
      <mass value="1.0"/>
      <origin xyz="0 0 0" rpy="0 0 0"/>
      <inertia ixx="0.001" ixy="0" ixz="0" iyy="0.001" iyz="0" izz="0.001"/>
    </inertial>
  </link>

  <!-- Joints — matching ROS-Industrial kinematic chain -->
  <!-- Added damping and friction for Gazebo stability -->
  <joint name="joint_1" type="revolute">
    <origin xyz="0 0 0.4" rpy="0 0 0"/>
    <parent link="base_link"/>
    <child link="link_1"/>
    <axis xyz="0 0 -1"/>
    <limit lower="-2.967059725" upper="2.967059725" effort="200" velocity="6.2832"/>
    <dynamics damping="10.0" friction="5.0"/>
  </joint>

  <joint name="joint_2" type="revolute">
    <origin xyz="0.025 0 0" rpy="0 0 0"/>
    <parent link="link_1"/>
    <child link="link_2"/>
    <axis xyz="0 1 0"/>
    <limit lower="-3.316125575" upper="0.785398163" effort="200" velocity="5.2360"/>
    <dynamics damping="10.0" friction="5.0"/>
  </joint>

  <joint name="joint_3" type="revolute">
    <origin xyz="0.315 0 0" rpy="0 0 0"/>
    <parent link="link_2"/>
    <child link="link_3"/>
    <axis xyz="0 1 0"/>
    <limit lower="-2.094395100" upper="2.722713630" effort="200" velocity="6.2832"/>
    <dynamics damping="10.0" friction="5.0"/>
  </joint>

  <joint name="joint_4" type="revolute">
    <origin xyz="0 0 0.035" rpy="0 0 0"/>
    <parent link="link_3"/>
    <child link="link_4"/>
    <axis xyz="-1 0 0"/>
    <limit lower="-3.228859113" upper="3.228859113" effort="100" velocity="6.6497"/>
    <dynamics damping="5.0" friction="2.0"/>
  </joint>

  <joint name="joint_5" type="revolute">
    <origin xyz="0.365 0 0" rpy="0 0 0"/>
    <parent link="link_4"/>
    <child link="link_5"/>
    <axis xyz="0 1 0"/>
    <limit lower="-2.094395100" upper="2.094395100" effort="100" velocity="6.7720"/>
    <dynamics damping="5.0" friction="2.0"/>
  </joint>

  <joint name="joint_6" type="revolute">
    <origin xyz="0.080 0 0" rpy="0 0 0"/>
    <parent link="link_5"/>
    <child link="link_6"/>
    <axis xyz="-1 0 0"/>
    <limit lower="-6.108652375" upper="6.108652375" effort="50" velocity="10.7338"/>
    <dynamics damping="2.0" friction="1.0"/>
  </joint>

</robot>
